Traceback (most recent call last):
  File "/Users/m/Uni/FoPra/Classes/Search.py", line 21, in driver_start
    self.driver = webdriver.Chrome('./chromedriver_osx')
  File "/Library/Frameworks/Python.framework/Versions/3.6/lib/python3.6/site-packages/selenium/webdriver/chrome/webdriver.py", line 75, in __init__
    desired_capabilities=desired_capabilities)
  File "/Library/Frameworks/Python.framework/Versions/3.6/lib/python3.6/site-packages/selenium/webdriver/remote/webdriver.py", line 154, in __init__
    self.start_session(desired_capabilities, browser_profile)
  File "/Library/Frameworks/Python.framework/Versions/3.6/lib/python3.6/site-packages/selenium/webdriver/remote/webdriver.py", line 243, in start_session
    response = self.execute(Command.NEW_SESSION, parameters)
  File "/Library/Frameworks/Python.framework/Versions/3.6/lib/python3.6/site-packages/selenium/webdriver/remote/webdriver.py", line 312, in execute
    self.error_handler.check_response(response)
  File "/Library/Frameworks/Python.framework/Versions/3.6/lib/python3.6/site-packages/selenium/webdriver/remote/errorhandler.py", line 242, in check_response
    raise exception_class(message, screen, stacktrace)
selenium.common.exceptions.SessionNotCreatedException: Message: session not created exception
from disconnected: unable to connect to renderer
  (Session info: chrome=66.0.3359.139)
  (Driver info: chromedriver=2.38.552518 (183d19265345f54ce39cbb94cf81ba5f15905011),platform=Mac OS X 10.11.6 x86_64)


During handling of the above exception, another exception occurred:

Traceback (most recent call last):
  File "ReadOnePage.py", line 15, in <module>
    search = Search()
  File "/Users/m/Uni/FoPra/Classes/Search.py", line 17, in __init__
    self.driver_start()
  File "/Users/m/Uni/FoPra/Classes/Search.py", line 23, in driver_start
    self.driver = webdriver.Chrome('./chromedriver_ubuntu')
  File "/Library/Frameworks/Python.framework/Versions/3.6/lib/python3.6/site-packages/selenium/webdriver/chrome/webdriver.py", line 68, in __init__
    self.service.start()
  File "/Library/Frameworks/Python.framework/Versions/3.6/lib/python3.6/site-packages/selenium/webdriver/common/service.py", line 76, in start
    stdin=PIPE)
  File "/Library/Frameworks/Python.framework/Versions/3.6/lib/python3.6/subprocess.py", line 709, in __init__
    restore_signals, start_new_session)
  File "/Library/Frameworks/Python.framework/Versions/3.6/lib/python3.6/subprocess.py", line 1344, in _execute_child
    raise child_exception_type(errno_num, err_msg, err_filename)
OSError: [Errno 8] Exec format error: './chromedriver_ubuntu'
